
Source file changed.
sqlalchemy.exc.OperationalError: (psycopg2.OperationalError) SSL connection has been closed unexpectedly [SQL: SELECT pg_catalog.pg_class.relname FROM pg_catalog.pg_class JOIN pg_catalog.pg_namespace ON pg_catalog.pg_namespace.oid = pg_catalog.pg_class.relnamespace WHERE pg_catalog.pg_class.relname = %(table_name)s AND pg_catalog.pg_class.relkind = ANY (ARRAY[%(param_1)s, %(param_2)s, %(param_3)s, %(param_4)s, %(param_5)s]) AND pg_catalog.pg_table_is_visible(pg_catalog.pg_class.oid) AND pg_catalog.pg_namespace.nspname != %(nspname_1)s] [parameters: {'table_name': 'users', 'param_1': 'r', 'param_2': 'p', 'param_3': 'f', 'param_4': 'v', 'param_5': 'm', 'nspname_1': 'pg_catalog'}] (Background on this error at: https://sqlalche.me/e/20/e3q8)
Traceback:

File "/home/runner/workspace/.pythonlibs/lib/python3.11/site-packages/streamlit/runtime/scriptrunner/exec_code.py", line 121, in exec_func_with_error_handling
    result = func()
             ^^^^^^
File "/home/runner/workspace/.pythonlibs/lib/python3.11/site-packages/streamlit/runtime/scriptrunner/script_runner.py", line 648, in code_to_exec
    exec(code, module.__dict__)
File "/home/runner/workspace/app.py", line 30, in <module>
    init_db()
File "/home/runner/workspace/models.py", line 80, in init_db
    Base.metadata.create_all(engine)
File "/home/runner/workspace/.pythonlibs/lib/python3.11/site-packages/sqlalchemy/sql/schema.py", line 5925, in create_all
    bind._run_ddl_visitor(
File "/home/runner/workspace/.pythonlibs/lib/python3.11/site-packages/sqlalchemy/engine/base.py", line 3249, in _run_ddl_visitor
    conn._run_ddl_visitor(visitorcallable, element, **kwargs)
File "/home/runner/workspace/.pythonlibs/lib/python3.11/site-packages/sqlalchemy/engine/base.py", line 2456, in _run_ddl_visitor
    visitorcallable(self.dialect, self, **kwargs).traverse_single(element)
File "/home/runner/workspace/.pythonlibs/lib/python3.11/site-packages/sqlalchemy/sql/visitors.py", line 664, in traverse_single
    return meth(obj, **kw)
           ^^^^^^^^^^^^^^^
File "/home/runner/workspace/.pythonlibs/lib/python3.11/site-packages/sqlalchemy/sql/ddl.py", line 960, in visit_metadata
    [t for t in tables if self._can_create_table(t)]
File "/home/runner/workspace/.pythonlibs/lib/python3.11/site-packages/sqlalchemy/sql/ddl.py", line 960, in <listcomp>
    [t for t in tables if self._can_create_table(t)]
                          ^^^^^^^^^^^^^^^^^^^^^^^^^
File "/home/runner/workspace/.pythonlibs/lib/python3.11/site-packages/sqlalchemy/sql/ddl.py", line 925, in _can_create_table
    return not self.checkfirst or not self.dialect.has_table(
                                      ^^^^^^^^^^^^^^^^^^^^^^^
File "<string>", line 2, in has_table
File "/home/runner/workspace/.pythonlibs/lib/python3.11/site-packages/sqlalchemy/engine/reflection.py", line 89, in cache
    return fn(self, con, *args, **kw)
           ^^^^^^^^^^^^^^^^^^^^^^^^^^
File "/home/runner/workspace/.pythonlibs/lib/python3.11/site-packages/sqlalchemy/dialects/postgresql/base.py", line 3414, in has_table
    return bool(connection.scalar(query, {"table_name": table_name}))
                ^^^^^^^^^^^^^^^^^^^^^^^^^^^^^^^^^^^^^^^^^^^^^^^^^^^^
File "/home/runner/workspace/.pythonlibs/lib/python3.11/site-packages/sqlalchemy/engine/base.py", line 1305, in scalar
    return meth(
           ^^^^^
File "/home/runner/workspace/.pythonlibs/lib/python3.11/site-packages/sqlalchemy/sql/elements.py", line 541, in _execute_on_scalar
    return self._execute_on_connection(
           ^^^^^^^^^^^^^^^^^^^^^^^^^^^^
File "/home/runner/workspace/.pythonlibs/lib/python3.11/site-packages/sqlalchemy/sql/elements.py", line 523, in _execute_on_connection
    return connection._execute_clauseelement(
           ^^^^^^^^^^^^^^^^^^^^^^^^^^^^^^^^^^
File "/home/runner/workspace/.pythonlibs/lib/python3.11/site-packages/sqlalchemy/engine/base.py", line 1638, in _execute_clauseelement
    ret = self._execute_context(
          ^^^^^^^^^^^^^^^^^^^^^^
File "/home/runner/workspace/.pythonlibs/lib/python3.11/site-packages/sqlalchemy/engine/base.py", line 1843, in _execute_context
    return self._exec_single_context(
           ^^^^^^^^^^^^^^^^^^^^^^^^^^
File "/home/runner/workspace/.pythonlibs/lib/python3.11/site-packages/sqlalchemy/engine/base.py", line 1983, in _exec_single_context
    self._handle_dbapi_exception(
File "/home/runner/workspace/.pythonlibs/lib/python3.11/site-packages/sqlalchemy/engine/base.py", line 2352, in _handle_dbapi_exception
    raise sqlalchemy_exception.with_traceback(exc_info[2]) from e
File "/home/runner/workspace/.pythonlibs/lib/python3.11/site-packages/sqlalchemy/engine/base.py", line 1964, in _exec_single_context
    self.dialect.do_execute(
File "/home/runner/workspace/.pythonlibs/lib/python3.11/site-packages/sqlalchemy/engine/default.py", line 945, in do_execute
    cursor.execute(statement, parameters)

